Workbook

Sheet ReadMe
A1: Chitrakala Inventory Sync Template - Updated to Match Actual DB Exports
A2: Paste refreshed DB export CSVs into the matching DB_* tabs starting at A1 including headers. The Inventory_Master, Potential_Issues_Auto, and Sync_Summary tabs update from formulas.
A4: DB_Artworks_Export exact columns | B4: id, title, category_slug, category_name, description, materials, price_inr, price_usd, fx_rate_used, multiplier_used, featured, image, created_at, updated_at
A5: DB_Artwork_Sizes_Export exact columns | B5: id, artwork_id, artwork_title, size_label, price, price_usd, created_at
A6: DB_Categories_Export exact columns | B6: id, name, description, image, display_order
A7: Do not edit DB tabs | B7: These tabs are raw exports. Replace/paste exports only, keeping the same column order.
A8: Inventory_Master | B8: DB columns are auto-populated from DB_Artworks_Export in the exact exported order. Do not type over DB columns. Use Corrected_* columns for proposed changes.
A9: Manual columns | B9: Sync Action, Inventory SKU, Corrected_* fields, Inventory Notes, Intern Review Notes.
A10: Formula columns | B10: Formula columns include Suggested Sync Action, Validation Status, DB current fields, Category Validation, Size Variant Count, First Size Label/Price fields, Size Review Flag, and Final_* fields.
A11: Potential_Issues_Auto | B11: Automatically flags invalid category, missing price, missing image, and size variant review rows.
A12: Reconciliation_Report | B12: Manual issue log. Use Potential_Issues_Auto to identify what to log.
A13: Import_Validation_Rules | B13: Updated for actual export columns. Add rules only if a new business rule is discovered.

Sheet Sync_Summary
A1: Chitrakala Inventory Sync Summary
A3: Metric | B3: Formula/Value | C3: Notes
A4: DB artworks count | B4: =MAX(COUNTA(DB_Artworks_Export!$A:$A)-1,0) -> 36 | C4: Rows in DB_Artworks_Export
A5: DB artwork size rows count | B5: =MAX(COUNTA(DB_Artwork_Sizes_Export!$A:$A)-1,0) -> 73 | C5: Rows in DB_Artwork_Sizes_Export
A6: DB categories count | B6: =MAX(COUNTA(DB_Categories_Export!$A:$A)-1,0) -> 5 | C6: Rows in DB_Categories_Export
A7: Inventory rows loaded | B7: =MAX(COUNTA(DB_Artworks_Export!$A:$A)-1,0) -> 36 | C7: Auto-populated from DB export
A8: Manual Sync Action - CREATE | B8: =COUNTIF(Inventory_Master!$A:$A,"CREATE") -> 0 | C8: Entered by intern
A9: Manual Sync Action - UPDATE | B9: =COUNTIF(Inventory_Master!$A:$A,"UPDATE") -> 9 | C9: Entered by intern
A10: Manual Sync Action - NO_CHANGE | B10: =COUNTIF(Inventory_Master!$A:$A,"NO_CHANGE") -> 27 | C10: Entered by intern
A11: Manual Sync Action - ARCHIVE | B11: =COUNTIF(Inventory_Master!$A:$A,"ARCHIVE") -> 0 | C11: Entered by intern
A12: Manual Sync Action - REVIEW | B12: =COUNTIF(Inventory_Master!$A:$A,"REVIEW") -> 0 | C12: Entered by intern
A13: Potential issue rows | B13: =COUNTIF(Potential_Issues_Auto!$G:$G,"YES") -> 33 | C13: Formula-driven issue helper
A14: Invalid category rows | B14: =COUNTIF(Inventory_Master!$R:$R,"INVALID CATEGORY") -> 0 | C14: Should be zero
A15: Size variant artworks | B15: =COUNTIF(Inventory_Master!$W:$W,"REVIEW_SIZE_PRICING") -> 33 | C15: Review size pricing
A16: Missing image rows | B16: =COUNTIF(Potential_Issues_Auto!$F:$F,"*Missing image*") -> 0 | C16: Review image path

Sheet ⚙️ Assumptions
B1: ⚙️ PRICING & COST ASSUMPTIONS
B2: All blue cells are inputs — update these as your costs change
B4: A. CURRENCY
B5: Parameter | C5: Value | D5: Notes
B6: INR to USD Exchange Rate | C6: 0.01059 | D6: Update weekly — e.g. 1 INR = 0.012 USD
B7: Buffer % for rate fluctuation | C7: 0.03 | D7: 3% buffer protects against rate moves
B9: B. SHIPPING & IMPORT COSTS
B10: Parameter | C10: Value | D10: Notes
B11: Base shipping cost per piece (USD) | C11: 45 | D11: Flat estimate; adjust by actual invoice
B12: Shipping cost per sq ft (USD) | C12: 8 | D12: For size-based calculation override
B13: US Customs duty rate (fine art) | C13: 0 | D13: Fine art (HTS 9701) is typically duty-free
B14: US Customs duty rate (decorative art) | C14: 0.065 | D14: Decorative art may attract ~6.5%
B15: Insurance rate (% of purchase price) | C15: 0.015 | D15: Typical transit insurance ~1.5%
B16: Customs brokerage flat fee (USD) | C16: 85 | D16: Per shipment; allocate across pieces
B17: Avg pieces per shipment | C17: 8 | D17: Used to allocate brokerage per piece
B18: Local delivery / handling (USD) | C18: 25 | D18: Last-mile to your storage/location
B20: C. OVERHEAD ALLOCATION
B21: Parameter | C21: Value | D21: Notes
B22: Monthly website / platform cost (USD) | C22: 49 | D22: Hosting, domain, e-commerce platform
B23: Monthly marketing spend (USD) | C23: 100 | D23: Social media ads, photography, etc.
B24: Monthly misc overhead (USD) | C24: 50 | D24: Packaging materials, admin costs
B25: Avg active inventory pieces | C25: 20 | D25: Used to allocate overhead per piece
B26: → Monthly Overhead Total | C26: =C22+C23+C24 -> 199 | D26: Auto-calculated from above
B27: → Overhead per Piece (USD) | C27: =C26/C25 -> 9.95 | D27: Allocated to each piece in inventory
B29: D. PRICING TIER MARKUPS
B30: Tier | C30: Markup on Landed Cost | D30: Applies When…
B31: Tier 1 — Standard | C31: 2.2 | D31: Unknown/emerging artist, common style
B32: Tier 2 — Mid-range | C32: 2.8 | D32: Recognized regional artist, quality medium
B33: Tier 3 — Premium | C33: 3.5 | D33: Established artist, rare style, large format
B34: Tier 4 — Collector | C34: 4.5 | D34: Signature/numbered work, high provenance
B35: Minimum margin floor | C35: 0.35 | D35: Never price below 35% gross margin
B37: COLOR KEY
B38: Blue text | C38: ■ ■ ■ | D38: Hardcoded input — you edit these
B39: Black text | C39: ■ ■ ■ | D39: Formula — auto-calculated, do not edit
B40: Green text | C40: ■ ■ ■ | D40: Cross-sheet link — pulls from another tab

Sheet DB_Artworks_Export
A1: id | B1: title | C1: category_slug | D1: category_name | E1: description | F1: materials | G1: price_inr | H1: price_usd | I1: fx_rate_used | J1: multiplier_used | K1: featured | L1: image | M1: created_at | N1: updated_at
A2: art-1770419263598 | B2: Eternal Glow – Mandala of Light and Balance | C2: dot-mandala | D2: Dot Mandala Art | E2: A striking hand-painted dot mandala artwork bursting with warmth and movement. Set against a deep black background, layers of flowing petal-like forms in rich shades of orange, amber, gold, and green radiate outward from a detailed center, creating a sense of balance and positive energy. Every dot and stroke is carefully placed by hand, making this piece truly one of a kind. Perfect as a statement wall décor or tabletop display, this mandala brings vibrancy and artistic depth to living rooms, meditation spaces, offices, or creative corners. An eye-catching handmade gift for housewarmings, festivals, weddings, or for anyone who appreciates meaningful, soulful art. | F2: Wood | G2: 4000.00 | H2: 76.00 | I2: 92.4000 | J2: 1.7500 | K2: f | L2: https://chitrakalaarts-production.up.railway.app/api/images/artworks/art-1770419263598 | M2: 2026-02-10 17:54:35.568324 | N2: 2026-03-17 03:31:03.482303
A3: art-1770419392051 | B3: Blush Serenity Mandala – Art in Soft Pink & White | C3: dot-mandala | D3: Dot Mandala Art | E3: A delicate hand-painted dot mandala artwork created in soothing blush pink and white tones. Intricate layers of flowing patterns and finely placed dots form a harmonious circular design that radiates calm, balance, and elegance. Each detail is painted by hand, making this artwork a truly one-of-a-kind piece. Perfect for adding a soft, peaceful touch to living rooms, bedrooms, meditation corners, or creative spaces, this mandala also makes a thoughtful handmade gift for housewarmings, weddings, anniversaries, or festive occasions. Its gentle color palette blends beautifully with modern, boho, and minimalist interiors. | F3: Wood | G3: 4000.00 | H3: 76.00 | I3: 92.4000 | J3: 1.7500 | K3: f | L3: https://chitrakalaarts-production.up.railway.app/api/images/artworks/art-1770419392051 | M3: 2026-02-10 17:54:35.568324 | N3: 2026-03-17 03:31:03.510591
A4: art-1770419460850 | B4: Mandala in Blue and Peach | C4: dot-mandala | D4: Dot Mandala Art | E4: A captivating hand-painted round dot mandala artwork created in serene shades of blue and soft peach. Layers of intricate dot work and flowing floral patterns come together in perfect harmony, evoking a sense of calm, warmth, and balance. The soothing blue tones bring tranquility, while the peach accents add a gentle glow, making this piece both peaceful and uplifting. Each mandala is carefully painted by hand, ensuring every artwork is unique. Perfect as a statement wall décor, shelf display, or meditation centerpiece, this mandala adds refined beauty to living rooms, bedrooms, yoga spaces, or creative corners. It also makes a thoughtful handmade gift for housewarmings, weddings, festivals, or special occasions. 18" - Rs 6200 24" Rs 8000 36" Rs 16000 | F4: Wood | G4: 4000.00 | H4: 76.00 | I4: 92.4000 | J4: 1.7500 | K4: f | L4: https://chitrakalaarts-production.up.railway.app/api/images/artworks/art-1770419460850 | M4: 2026-02-10 17:54:35.568324 | N4: 2026-03-17 03:31:03.532958
A5: art-1770771760544 | B5: Hand-Painted Keychains (set of 5) | C5: dot-mandala | D5: Dot Mandala Art | E5: Brighten someone’s day with these hand-painted dot mandala wooden keychains, full of color and joyful detail. A thoughtful and affordable gift for festivals, return gifts, party favors, or stocking stuffers—each piece handmade to spread happiness and charm. | F5: Wood | G5: 450.00 | H5: 9.00 | I5: 92.4000 | J5: 1.7500 | K5: f | L5: https://chitrakalaarts-production.up.railway.app/api/images/artworks/art-1770771760544 | M5: 2026-02-11 01:02:40.581985 | N5: 2026-03-17 03:31:03.473272
A6: art-1770771970545 | B6: Mango-Shaped storage box | C6: dot-mandala | D6: Dot Mandala Art | E6: Unique hand-painted mango-shaped wooden storage box decorated with detailed dot mandala artwork. Ideal for storing jewelry, trinkets, or small keepsakes while bringing a playful yet traditional artistic touch to your décor. | F6: Wood | G6: 450.00 | H6: 9.00 | I6: 92.4000 | J6: 1.7500 | K6: f | L6: https://chitrakalaarts-production.up.railway.app/api/images/artworks/art-1770771970545 | M6: 2026-02-11 01:06:10.580553 | N6: 2026-03-17 03:31:03.469417
A7: art-1770775579766 | B7: Intricate Floral Mandala Art in Green & Gold | C7: dot-mandala | D7: Dot Mandala Art | E7: An exquisite hand-painted dot mandala artwork, created with intricate layers of delicate dots and flowing floral patterns. Painted in soothing green and warm gold tones, this mandala radiates harmony, balance, and timeless beauty. Every detail is carefully handcrafted, making each piece truly one of a kind. Perfect as a statement wall décor, shelf accent, or meditation centerpiece, this mandala art brings a sense of calm and elegance to living rooms, entryways, yoga spaces, or gifting occasions. A meaningful handmade gift for art lovers, housewarmings, weddings, or festive celebrations. | F7: wood | G7: 4000.00 | H7: 76.00 | I7: 92.4000 | J7: 1.7500 | K7: t | L7: https://chitrakalaarts-production.up.railway.app/api/images/artworks/art-1770775579766 | M7: 2026-02-11 02:06:19.802205 | N7: 2026-03-17 03:31:03.464546
A8: art-1770777152872 | B8: Sacred Geometry in Clay & Mirror | C8: lippan-art | D8: Lippan Art | E8: A stunning Lippan art panel handcrafted with clay motifs and delicate mirror inlays, radiating harmony through its geometric symmetry. Framed by vibrant earthy tones, it brings a serene glow to any space. | F8: Wood | G8: 8000.00 | H8: 152.00 | I8: 92.4000 | J8: 1.7500 | K8: f | L8: https://chitrakalaarts-production.up.railway.app/api/images/artworks/art-1770777152872 | M8: 2026-02-11 02:32:32.911059 | N8: 2026-04-28 17:54:38.817767
A9: art-1770778179564 | B9: Colorful Mandala KeyChain Holder | C9: dot-mandala | D9: Dot Mandala Art | E9: Handcrafted wooden key holder adorned with a vibrant dot mandala design in calming shades of purple and teal. Finished with sturdy hooks, it’s perfect for organizing keys while adding a touch of artistic elegance to your home décor. A beautiful blend of functionality and mindful art—ideal for entryways or as a thoughtful handmade gift. | F9: Wood | G9: 1000.00 | H9: 19.00 | I9: 92.4000 | J9: 1.7500 | K9: f | L9: https://chitrakalaarts-production.up.railway.app/api/images/artworks/art-1770778179564 | M9: 2026-02-11 02:49:39.60251 | N9: 2026-03-17 03:31:03.453632
A10: art-1770778384172 | B10: Butterfly Set (3 pieces) | C10: dot-mandala | D10: Dot Mandala Art | E10: A graceful butterfly brought to life through intricate dot mandala artistry, this hand-painted piece symbolizes transformation, joy, and renewal. Rendered in warm shades of gold, green, and soft orange, each delicate dot adds depth, movement, and a gentle sense of harmony. Perfect as a mindful décor piece, this artwork radiates elegance and positive energy—an exquisite reminder of beauty in transformation. Available in set of 3 - 8*, 6", 4" | F10: Wood | G10: 1500.00 | H10: 28.00 | I10: 92.4000 | J10: 1.7500 | K10: f | L10: https://chitrakalaarts-production.up.railway.app/api/images/artworks/art-1770778384172 | M10: 2026-02-11 02:53:04.203783 | N10: 2026-03-17 03:31:03.447787
A11: art-1770778509370 | B11: Coaster Set (4 pieces) | C11: dot-mandala | D11: Dot Mandala Art | E11: Add a touch of handcrafted elegance to your everyday moments with this hand-painted dot mandala coaster set. Each coaster is meticulously adorned with intricate dot patterns, radiating symmetry, balance, and calming energy. The rich colors and delicate detailing create a harmonious blend of art and function, protecting your surfaces while elevating your décor. Perfect for tea tables, coffee corners, or thoughtful gifting, this coaster set brings mindful beauty and artisanal charm into every sip. Set of 4 - Rs 750 Set of 6 - Rs 1000 | F11: Wood | G11: 800.00 | H11: 15.00 | I11: 92.4000 | J11: 1.7500 | K11: f | L11: https://chitrakalaarts-production.up.railway.app/api/images/artworks/art-1770778509370 | M11: 2026-02-11 02:55:09.407983 | N11: 2026-03-17 03:31:03.442637
A12: art-1770778808201 | B12: Serene Teal Floral Mandala Box | C12: dot-mandala | D12: Dot Mandala Art | E12: Hand-painted dot mandala box in soothing teal and turquoise tones, adorned with intricate floral patterns. A perfect accent piece for storing jewelry, keys, or small keepsakes—bringing calm, color, and handmade charm to any space | F12: Wood | G12: 1000.00 | H12: 19.00 | I12: 92.4000 | J12: 1.7500 | K12: f | L12: https://chitrakalaarts-production.up.railway.app/api/images/artworks/art-1770778808201 | M12: 2026-02-11 03:00:08.235036 | N12: 2026-03-17 03:31:03.439328
... A37: art-1778384550442 | B37: Moonlit Lotus – White Mirror Mosaic Art Work | C37: mirror-mosaic | D37: Mirror Mosaic | E37: Delicate, luminous, and intricately detailed, this white mirror mosaic artwork draws inspiration from blooming lotus patterns and traditional mandala artistry. The soft textured white finish combined with shimmering mirror inlays creates a serene yet luxurious presence, reflecting light beautifully from every angle. Handcrafted with precision, this elegant piece symbolizes harmony, purity, and balance, making it a perfect addition to contemporary, minimal, or spiritual interiors. Its timeless design brings calm sophistication and artistic depth to any wall or décor setting. | F37: Glass Mirrors Cuttings | G37: 13500.00 | H37: 256.00 | I37: 92.4000 | J37: 1.7500 | K37: f | L37: https://chitrakalaarts-production.up.railway.app/api/images/artworks/art-1778384550442 | M37: 2026-05-10 03:42:30.476539 | N37: 2026-05-10 03:42:30.676559

Sheet DB_Artwork_Sizes_Export
A1: id | B1: artwork_id | C1: artwork_title | D1: size_label | E1: price | F1: price_usd | G1: created_at
A2: 608 | B2: art-1770419263598 | C2: Eternal Glow – Mandala of Light and Balance | D2: 12" x 12" | E2: 4500.00 | F2: 76.00 | G2: 2026-03-17 03:31:03.509704
A3: 609 | B3: art-1770419263598 | C3: Eternal Glow – Mandala of Light and Balance | D3: 18" x 18" | E3: 7500.00 | F3: 76.00 | G3: 2026-03-17 03:31:03.509704
A4: 610 | B4: art-1770419263598 | C4: Eternal Glow – Mandala of Light and Balance | D4: 24" x 24" | E4: 10000.00 | F4: 76.00 | G4: 2026-03-17 03:31:03.509704
A5: 611 | B5: art-1770419263598 | C5: Eternal Glow – Mandala of Light and Balance | D5: 36" x 36" | E5: 20000.00 | F5: 76.00 | G5: 2026-03-17 03:31:03.509704
A6: 612 | B6: art-1770419460850 | C6: Mandala in Blue and Peach | D6: 12" | E6: 3500.00 | F6: 76.00 | G6: 2026-03-17 03:31:03.539472
A7: 607 | B7: art-1770771760544 | C7: Hand-Painted Keychains (set of 5) | D7: custom | E7: 450.00 | F7: 9.00 | G7: 2026-03-17 03:31:03.4795
A8: 606 | B8: art-1770771970545 | C8: Mango-Shaped storage box | D8: 4" X 2" | E8: 450.00 | F8: 9.00 | G8: 2026-03-17 03:31:03.472348
A9: 602 | B9: art-1770775579766 | C9: Intricate Floral Mandala Art in Green & Gold | D9: 12" round | E9: 4000.00 | F9: 76.00 | G9: 2026-03-17 03:31:03.468752
A10: 603 | B10: art-1770775579766 | C10: Intricate Floral Mandala Art in Green & Gold | D10: 18" round | E10: 6900.00 | F10: 76.00 | G10: 2026-03-17 03:31:03.468752
A11: 604 | B11: art-1770775579766 | C11: Intricate Floral Mandala Art in Green & Gold | D11: 24" round | E11: 9000.00 | F11: 76.00 | G11: 2026-03-17 03:31:03.468752
A12: 605 | B12: art-1770775579766 | C12: Intricate Floral Mandala Art in Green & Gold | D12: 36" round | E12: 18000.00 | F12: 76.00 | G12: 2026-03-17 03:31:03.468752
... A74: 644 | B74: art-1778384550442 | C74: Moonlit Lotus – White Mirror Mosaic Art Work | D74: 12"x12" | E74: 13500.00 | F74: 256.00 | G74: 2026-05-10 03:42:30.477433

Sheet DB_Categories_Export
A1: id | B1: name | C1: description | D1: image | E1: display_order
A2: dot-mandala | B2: Dot Mandala Art | C2: Intricate dot patterns creating beautiful mandala designs, combining precision and creativity. | D2: /assets/images/categories/dot-mandala.png | E2: 1
A3: lippan-art | B3: Lippan Art | C3: Traditional mirror and clay work art from Gujarat, featuring stunning geometric patterns. | D3: /assets/images/categories/lippan-art.png | E3: 2
A4: mirror-mosaic | B4: Mirror Mosaic | C4: Carefully arranged mirrored elements that catch and scatter light, adding depth, texture, and a subtle shimmer to any space. | D4: /assets/images/categories/mirror-mosaic.png | E4: 3
A5: textile-design | B5: Textile Art | C5: Hand-painted and designed textile pieces that blend tradition with contemporary aesthetics. | D5: /assets/images/categories/textile-design.png | E5: 5
A6: texture-art | B6: Texture Art | C6: Handcrafted pieces where dimension meets design, with layered details, soft depth, and tactile finishes that bring walls to life. | D6: /assets/images/categories/texture-art.png | E6: 4

Sheet Inventory_Master
A1: Sync Action | B1: Suggested Sync Action | C1: Validation Status | D1: DB id | E1: DB title | F1: DB category_slug | G1: DB category_name | H1: DB description | I1: DB materials | J1: DB price_inr | K1: DB price_usd | L1: DB fx_rate_used | M1: DB multiplier_used | N1: DB featured | O1: DB image | P1: DB created_at | Q1: DB updated_at | R1: Category Validation | S1: Size Variant Count | T1: First Size Label | U1: First Size Price INR | V1: First Size Price USD | W1: Size Review Flag | X1: Inventory SKU | Y1: Corrected title | Z1: Corrected category_slug | AA1: Corrected description | AB1: Corrected materials | AC1: Corrected price_inr | AD1: Corrected featured | AE1: Corrected image | AF1: Final title | AG1: Final category_slug | AH1: Final category_name | AI1: Final description | AJ1: Final materials | AK1: Final price_inr | AL1: Final featured | AM1: Final image | AN1: Inventory Notes | AO1: Intern Review Notes
A2: NO_CHANGE | B2: =IF($D2="","",IF(COUNTA($Y2:$AE2)>0,"UPDATE","NO_CHANGE")) -> NO_CHANGE | C2: =IF($D2="","",IF($R2<>"OK","ERROR",IF(OR($E2="", $F2="", $J2=""),"ERROR",IF($W2<>"OK","WARNING","PASS")))) -> WARNING | D2: =IF(DB_Artworks_Export!A2="","",DB_Artworks_Export!A2) -> art-1770419263598 | E2: =IF(DB_Artworks_Export!B2="","",DB_Artworks_Export!B2) -> Eternal Glow – Mandala of Light and Balance | F2: =IF(DB_Artworks_Export!C2="","",DB_Artworks_Export!C2) -> dot-mandala | G2: =IF(DB_Artworks_Export!D2="","",DB_Artworks_Export!D2) -> Dot Mandala Art | H2: =IF(DB_Artworks_Export!E2="","",DB_Artworks_Export!E2) -> A striking hand-painted dot mandala artwork bursting with warmth and movement. Set against a deep black background, layers of flowing petal-like forms in rich shades of orange, amber, gold, and green radiate outward from a detailed center, creating a sense of balance and positive energy. Every dot and stroke is carefully placed by hand, making this piece truly one of a kind. Perfect as a statement wall décor or tabletop display, this mandala brings vibrancy and artistic depth to living rooms, meditation spaces, offices, or creative corners. An eye-catching handmade gift for housewarmings, festivals, weddings, or for anyone who appreciates meaningful, soulful art. | I2: =IF(DB_Artworks_Export!F2="","",DB_Artworks_Export!F2) -> Wood | J2: =IF(DB_Artworks_Export!G2="","",DB_Artworks_Export!G2) -> 4000.00 | K2: =IF(DB_Artworks_Export!H2="","",DB_Artworks_Export!H2) -> 76.00 | ... Q2: =IF(DB_Artworks_Export!N2="","",DB_Artworks_Export!N2) -> 2026-03-17 03:31:03.482303 | R2: =IF($D2="","",IF(COUNTIF(DB_Categories_Export!$A:$A,$F2)>0,"OK","INVALID CATEGORY")) -> OK | S2: =IF($D2="","",COUNTIF(DB_Artwork_Sizes_Export!$B:$B,$D2)) -> 4 | T2: =IF($D2="","",IFERROR(INDEX(DB_Artwork_Sizes_Export!$D:$D,MATCH($D2,DB_Artwork_Sizes_Export!$B:$B,0)),"")) -> 12" x 12" | U2: =IF($D2="","",IFERROR(INDEX(DB_Artwork_Sizes_Export!$E:$E,MATCH($D2,DB_Artwork_Sizes_Export!$B:$B,0)),"")) -> 4500.00 | V2: =IF($D2="","",IFERROR(INDEX(DB_Artwork_Sizes_Export!$F:$F,MATCH($D2,DB_Artwork_Sizes_Export!$B:$B,0)),"")) -> 76.00 | W2: =IF($D2="","",IF($S2>0,"REVIEW_SIZE_PRICING","OK")) -> REVIEW_SIZE_PRICING | AF2: =IF($Y2<>"",$Y2,$E2) -> Eternal Glow – Mandala of Light and Balance | AG2: =IF($Z2<>"",$Z2,$F2) -> dot-mandala | AH2: =IF($AG2="","",IFERROR(VLOOKUP($AG2,DB_Categories_Export!$A:$B,2,FALSE()),"INVALID CATEGORY")) -> Dot Mandala Art | AI2: =IF($AA2<>"",$AA2,$H2) -> A striking hand-painted dot mandala artwork bursting with warmth and movement. Set against a deep black background, layers of flowing petal-like forms in rich shades of orange, amber, gold, and green radiate outward from a detailed center, creating a sense of balance and positive energy. Every dot and stroke is carefully placed by hand, making this piece truly one of a kind. Perfect as a statement wall décor or tabletop display, this mandala brings vibrancy and artistic depth to living rooms, meditation spaces, offices, or creative corners. An eye-catching handmade gift for housewarmings, festivals, weddings, or for anyone who appreciates meaningful, soulful art. | AJ2: =IF($AB2<>"",$AB2,$I2) -> Wood | AK2: =IF($AC2<>"",$AC2,$J2) -> 4000.00 | AL2: =IF($AD2<>"",$AD2,$N2) -> f | AM2: =IF($AE2<>"",$AE2,$O2) -> https://chitrakalaarts-production.up.railway.app/api/images/artworks/art-1770419263598 | AO2: INV-03-01 reviewed: final action NO_CHANGE for artwork-level fields. Suggested Sync Action was NO_CHANGE and current artwork fields/category validate. REVIEW was driven by size-level pricing review flag; defer size-level USD/variant pricing to pricing subtask. No Corrected_* fields needed.
A3: NO_CHANGE | B3: =IF($D3="","",IF(COUNTA($Y3:$AE3)>0,"UPDATE","NO_CHANGE")) -> NO_CHANGE | C3: =IF($D3="","",IF($R3<>"OK","ERROR",IF(OR($E3="", $F3="", $J3=""),"ERROR",IF($W3<>"OK","WARNING","PASS")))) -> PASS | D3: =IF(DB_Artworks_Export!A3="","",DB_Artworks_Export!A3) -> art-1770419392051 | E3: =IF(DB_Artworks_Export!B3="","",DB_Artworks_Export!B3) -> Blush Serenity Mandala – Art in Soft Pink & White | F3: =IF(DB_Artworks_Export!C3="","",DB_Artworks_Export!C3) -> dot-mandala | G3: =IF(DB_Artworks_Export!D3="","",DB_Artworks_Export!D3) -> Dot Mandala Art | H3: =IF(DB_Artworks_Export!E3="","",DB_Artworks_Export!E3) -> A delicate hand-painted dot mandala artwork created in soothing blush pink and white tones. Intricate layers of flowing patterns and finely placed dots form a harmonious circular design that radiates calm, balance, and elegance. Each detail is painted by hand, making this artwork a truly one-of-a-kind piece. Perfect for adding a soft, peaceful touch to living rooms, bedrooms, meditation corners, or creative spaces, this mandala also makes a thoughtful handmade gift for housewarmings, weddings, anniversaries, or festive occasions. Its gentle color palette blends beautifully with modern, boho, and minimalist interiors. | I3: =IF(DB_Artworks_Export!F3="","",DB_Artworks_Export!F3) -> Wood | J3: =IF(DB_Artworks_Export!G3="","",DB_Artworks_Export!G3) -> 4000.00 | K3: =IF(DB_Artworks_Export!H3="","",DB_Artworks_Export!H3) -> 76.00 | ... Q3: =IF(DB_Artworks_Export!N3="","",DB_Artworks_Export!N3) -> 2026-03-17 03:31:03.510591 | R3: =IF($D3="","",IF(COUNTIF(DB_Categories_Export!$A:$A,$F3)>0,"OK","INVALID CATEGORY")) -> OK | S3: =IF($D3="","",COUNTIF(DB_Artwork_Sizes_Export!$B:$B,$D3)) -> 0 | T3: =IF($D3="","",IFERROR(INDEX(DB_Artwork_Sizes_Export!$D:$D,MATCH($D3,DB_Artwork_Sizes_Export!$B:$B,0)),"")) | U3: =IF($D3="","",IFERROR(INDEX(DB_Artwork_Sizes_Export!$E:$E,MATCH($D3,DB_Artwork_Sizes_Export!$B:$B,0)),"")) | V3: =IF($D3="","",IFERROR(INDEX(DB_Artwork_Sizes_Export!$F:$F,MATCH($D3,DB_Artwork_Sizes_Export!$B:$B,0)),"")) | W3: =IF($D3="","",IF($S3>0,"REVIEW_SIZE_PRICING","OK")) -> OK | AF3: =IF($Y3<>"",$Y3,$E3) -> Blush Serenity Mandala – Art in Soft Pink & White | AG3: =IF($Z3<>"",$Z3,$F3) -> dot-mandala | AH3: =IF($AG3="","",IFERROR(VLOOKUP($AG3,DB_Categories_Export!$A:$B,2,FALSE()),"INVALID CATEGORY")) -> Dot Mandala Art | AI3: =IF($AA3<>"",$AA3,$H3) -> A delicate hand-painted dot mandala artwork created in soothing blush pink and white tones. Intricate layers of flowing patterns and finely placed dots form a harmonious circular design that radiates calm, balance, and elegance. Each detail is painted by hand, making this artwork a truly one-of-a-kind piece. Perfect for adding a soft, peaceful touch to living rooms, bedrooms, meditation corners, or creative spaces, this mandala also makes a thoughtful handmade gift for housewarmings, weddings, anniversaries, or festive occasions. Its gentle color palette blends beautifully with modern, boho, and minimalist interiors. | AJ3: =IF($AB3<>"",$AB3,$I3) -> Wood | AK3: =IF($AC3<>"",$AC3,$J3) -> 4000.00 | AL3: =IF($AD3<>"",$AD3,$N3) -> f | AM3: =IF($AE3<>"",$AE3,$O3) -> https://chitrakalaarts-production.up.railway.app/api/images/artworks/art-1770419392051
A4: UPDATE | B4: =IF($D4="","",IF(COUNTA($Y4:$AE4)>0,"UPDATE","NO_CHANGE")) -> UPDATE | C4: =IF($D4="","",IF($R4<>"OK","ERROR",IF(OR($E4="", $F4="", $J4=""),"ERROR",IF($W4<>"OK","WARNING","PASS")))) -> WARNING | D4: =IF(DB_Artworks_Export!A4="","",DB_Artworks_Export!A4) -> art-1770419460850 | E4: =IF(DB_Artworks_Export!B4="","",DB_Artworks_Export!B4) -> Mandala in Blue and Peach | F4: =IF(DB_Artworks_Export!C4="","",DB_Artworks_Export!C4) -> dot-mandala | G4: =IF(DB_Artworks_Export!D4="","",DB_Artworks_Export!D4) -> Dot Mandala Art | H4: =IF(DB_Artworks_Export!E4="","",DB_Artworks_Export!E4) -> A captivating hand-painted round dot mandala artwork created in serene shades of blue and soft peach. Layers of intricate dot work and flowing floral patterns come together in perfect harmony, evoking a sense of calm, warmth, and balance. The soothing blue tones bring tranquility, while the peach accents add a gentle glow, making this piece both peaceful and uplifting. Each mandala is carefully painted by hand, ensuring every artwork is unique. Perfect as a statement wall décor, shelf display, or meditation centerpiece, this mandala adds refined beauty to living rooms, bedrooms, yoga spaces, or creative corners. It also makes a thoughtful handmade gift for housewarmings, weddings, festivals, or special occasions. 18" - Rs 6200 24" Rs 8000 36" Rs 16000 | I4: =IF(DB_Artworks_Export!F4="","",DB_Artworks_Export!F4) -> Wood | J4: =IF(DB_Artworks_Export!G4="","",DB_Artworks_Export!G4) -> 4000.00 | K4: =IF(DB_Artworks_Export!H4="","",DB_Artworks_Export!H4) -> 76.00 | ... Q4: =IF(DB_Artworks_Export!N4="","",DB_Artworks_Export!N4) -> 2026-03-17 03:31:03.532958 | R4: =IF($D4="","",IF(COUNTIF(DB_Categories_Export!$A:$A,$F4)>0,"OK","INVALID CATEGORY")) -> OK | S4: =IF($D4="","",COUNTIF(DB_Artwork_Sizes_Export!$B:$B,$D4)) -> 1 | T4: =IF($D4="","",IFERROR(INDEX(DB_Artwork_Sizes_Export!$D:$D,MATCH($D4,DB_Artwork_Sizes_Export!$B:$B,0)),"")) -> 12" | U4: =IF($D4="","",IFERROR(INDEX(DB_Artwork_Sizes_Export!$E:$E,MATCH($D4,DB_Artwork_Sizes_Export!$B:$B,0)),"")) -> 3500.00 | V4: =IF($D4="","",IFERROR(INDEX(DB_Artwork_Sizes_Export!$F:$F,MATCH($D4,DB_Artwork_Sizes_Export!$B:$B,0)),"")) -> 76.00 | W4: =IF($D4="","",IF($S4>0,"REVIEW_SIZE_PRICING","OK")) -> REVIEW_SIZE_PRICING | AA4: A captivating hand-painted round dot mandala artwork created in serene shades of blue and soft peach. Layers of intricate dot work and flowing floral patterns come together in perfect harmony, evoking a sense of calm, warmth, and balance. The soothing blue tones bring tranquility, while the peach accents add a gentle glow, making this piece both peaceful and uplifting. Each mandala is carefully painted by hand, ensuring every artwork is unique. Perfect as a statement wall décor, shelf display, or meditation centerpiece, this mandala adds refined beauty to living rooms, bedrooms, yoga spaces, or creative corners. It also makes a thoughtful handmade gift for housewarmings, weddings, festivals, or special occasions. | AF4: =IF($Y4<>"",$Y4,$E4) -> Mandala in Blue and Peach | AG4: =IF($Z4<>"",$Z4,$F4) -> dot-mandala | AH4: =IF($AG4="","",IFERROR(VLOOKUP($AG4,DB_Categories_Export!$A:$B,2,FALSE()),"INVALID CATEGORY")) -> Dot Mandala Art | AI4: =IF($AA4<>"",$AA4,$H4) -> A captivating hand-painted round dot mandala artwork created in serene shades of blue and soft peach. Layers of intricate dot work and flowing floral patterns come together in perfect harmony, evoking a sense of calm, warmth, and balance. The soothing blue tones bring tranquility, while the peach accents add a gentle glow, making this piece both peaceful and uplifting. Each mandala is carefully painted by hand, ensuring every artwork is unique. Perfect as a statement wall décor, shelf display, or meditation centerpiece, this mandala adds refined beauty to living rooms, bedrooms, yoga spaces, or creative corners. It also makes a thoughtful handmade gift for housewarmings, weddings, festivals, or special occasions. | AJ4: =IF($AB4<>"",$AB4,$I4) -> Wood | AK4: =IF($AC4<>"",$AC4,$J4) -> 4000.00 | AL4: =IF($AD4<>"",$AD4,$N4) -> f | AM4: =IF($AE4<>"",$AE4,$O4) -> https://chitrakalaarts-production.up.railway.app/api/images/artworks/art-1770419460850
A5: NO_CHANGE | B5: =IF($D5="","",IF(COUNTA($Y5:$AE5)>0,"UPDATE","NO_CHANGE")) -> NO_CHANGE | C5: =IF($D5="","",IF($R5<>"OK","ERROR",IF(OR($E5="", $F5="", $J5=""),"ERROR",IF($W5<>"OK","WARNING","PASS")))) -> WARNING | D5: =IF(DB_Artworks_Export!A5="","",DB_Artworks_Export!A5) -> art-1770771760544 | E5: =IF(DB_Artworks_Export!B5="","",DB_Artworks_Export!B5) -> Hand-Painted Keychains (set of 5) | F5: =IF(DB_Artworks_Export!C5="","",DB_Artworks_Export!C5) -> dot-mandala | G5: =IF(DB_Artworks_Export!D5="","",DB_Artworks_Export!D5) -> Dot Mandala Art | H5: =IF(DB_Artworks_Export!E5="","",DB_Artworks_Export!E5) -> Brighten someone’s day with these hand-painted dot mandala wooden keychains, full of color and joyful detail. A thoughtful and affordable gift for festivals, return gifts, party favors, or stocking stuffers—each piece handmade to spread happiness and charm. | I5: =IF(DB_Artworks_Export!F5="","",DB_Artworks_Export!F5) -> Wood | J5: =IF(DB_Artworks_Export!G5="","",DB_Artworks_Export!G5) -> 450.00 | K5: =IF(DB_Artworks_Export!H5="","",DB_Artworks_Export!H5) -> 9.00 | ... Q5: =IF(DB_Artworks_Export!N5="","",DB_Artworks_Export!N5) -> 2026-03-17 03:31:03.473272 | R5: =IF($D5="","",IF(COUNTIF(DB_Categories_Export!$A:$A,$F5)>0,"OK","INVALID CATEGORY")) -> OK | S5: =IF($D5="","",COUNTIF(DB_Artwork_Sizes_Export!$B:$B,$D5)) -> 1 | T5: =IF($D5="","",IFERROR(INDEX(DB_Artwork_Sizes_Export!$D:$D,MATCH($D5,DB_Artwork_Sizes_Export!$B:$B,0)),"")) -> custom | U5: =IF($D5="","",IFERROR(INDEX(DB_Artwork_Sizes_Export!$E:$E,MATCH($D5,DB_Artwork_Sizes_Export!$B:$B,0)),"")) -> 450.00 | V5: =IF($D5="","",IFERROR(INDEX(DB_Artwork_Sizes_Export!$F:$F,MATCH($D5,DB_Artwork_Sizes_Export!$B:$B,0)),"")) -> 9.00 | W5: =IF($D5="","",IF($S5>0,"REVIEW_SIZE_PRICING","OK")) -> REVIEW_SIZE_PRICING | AF5: =IF($Y5<>"",$Y5,$E5) -> Hand-Painted Keychains (set of 5) | AG5: =IF($Z5<>"",$Z5,$F5) -> dot-mandala | AH5: =IF($AG5="","",IFERROR(VLOOKUP($AG5,DB_Categories_Export!$A:$B,2,FALSE()),"INVALID CATEGORY")) -> Dot Mandala Art | AI5: =IF($AA5<>"",$AA5,$H5) -> Brighten someone’s day with these hand-painted dot mandala wooden keychains, full of color and joyful detail. A thoughtful and affordable gift for festivals, return gifts, party favors, or stocking stuffers—each piece handmade to spread happiness and charm. | AJ5: =IF($AB5<>"",$AB5,$I5) -> Wood | AK5: =IF($AC5<>"",$AC5,$J5) -> 450.00 | AL5: =IF($AD5<>"",$AD5,$N5) -> f | AM5: =IF($AE5<>"",$AE5,$O5) -> https://chitrakalaarts-production.up.railway.app/api/images/artworks/art-1770771760544 | AO5: INV-03-01 reviewed: final action NO_CHANGE for artwork-level fields. Suggested Sync Action was NO_CHANGE and current artwork fields/category validate. REVIEW was driven by size-level pricing review flag; defer size-level USD/variant pricing to pricing subtask. No Corrected_* fields needed.
A6: NO_CHANGE | B6: =IF($D6="","",IF(COUNTA($Y6:$AE6)>0,"UPDATE","NO_CHANGE")) -> NO_CHANGE | C6: =IF($D6="","",IF($R6<>"OK","ERROR",IF(OR($E6="", $F6="", $J6=""),"ERROR",IF($W6<>"OK","WARNING","PASS")))) -> WARNING | D6: =IF(DB_Artworks_Export!A6="","",DB_Artworks_Export!A6) -> art-1770771970545 | E6: =IF(DB_Artworks_Export!B6="","",DB_Artworks_Export!B6) -> Mango-Shaped storage box | F6: =IF(DB_Artworks_Export!C6="","",DB_Artworks_Export!C6) -> dot-mandala | G6: =IF(DB_Artworks_Export!D6="","",DB_Artworks_Export!D6) -> Dot Mandala Art | H6: =IF(DB_Artworks_Export!E6="","",DB_Artworks_Export!E6) -> Unique hand-painted mango-shaped wooden storage box decorated with detailed dot mandala artwork. Ideal for storing jewelry, trinkets, or small keepsakes while bringing a playful yet traditional artistic touch to your décor. | I6: =IF(DB_Artworks_Export!F6="","",DB_Artworks_Export!F6) -> Wood | J6: =IF(DB_Artworks_Export!G6="","",DB_Artworks_Export!G6) -> 450.00 | K6: =IF(DB_Artworks_Export!H6="","",DB_Artworks_Export!H6) -> 9.00 | ... Q6: =IF(DB_Artworks_Export!N6="","",DB_Artworks_Export!N6) -> 2026-03-17 03:31:03.469417 | R6: =IF($D6="","",IF(COUNTIF(DB_Categories_Export!$A:$A,$F6)>0,"OK","INVALID CATEGORY")) -> OK | S6: =IF($D6="","",COUNTIF(DB_Artwork_Sizes_Export!$B:$B,$D6)) -> 1 | T6: =IF($D6="","",IFERROR(INDEX(DB_Artwork_Sizes_Export!$D:$D,MATCH($D6,DB_Artwork_Sizes_Export!$B:$B,0)),"")) -> 4" X 2" | U6: =IF($D6="","",IFERROR(INDEX(DB_Artwork_Sizes_Export!$E:$E,MATCH($D6,DB_Artwork_Sizes_Export!$B:$B,0)),"")) -> 450.00 | V6: =IF($D6="","",IFERROR(INDEX(DB_Artwork_Sizes_Export!$F:$F,MATCH($D6,DB_Artwork_Sizes_Export!$B:$B,0)),"")) -> 9.00 | W6: =IF($D6="","",IF($S6>0,"REVIEW_SIZE_PRICING","OK")) -> REVIEW_SIZE_PRICING | AF6: =IF($Y6<>"",$Y6,$E6) -> Mango-Shaped storage box | AG6: =IF($Z6<>"",$Z6,$F6) -> dot-mandala | AH6: =IF($AG6="","",IFERROR(VLOOKUP($AG6,DB_Categories_Export!$A:$B,2,FALSE()),"INVALID CATEGORY")) -> Dot Mandala Art | AI6: =IF($AA6<>"",$AA6,$H6) -> Unique hand-painted mango-shaped wooden storage box decorated with detailed dot mandala artwork. Ideal for storing jewelry, trinkets, or small keepsakes while bringing a playful yet traditional artistic touch to your décor. | AJ6: =IF($AB6<>"",$AB6,$I6) -> Wood | AK6: =IF($AC6<>"",$AC6,$J6) -> 450.00 | AL6: =IF($AD6<>"",$AD6,$N6) -> f | AM6: =IF($AE6<>"",$AE6,$O6) -> https://chitrakalaarts-production.up.railway.app/api/images/artworks/art-1770771970545 | AO6: INV-03-01 reviewed: final action NO_CHANGE for artwork-level fields. Suggested Sync Action was NO_CHANGE and current artwork fields/category validate. REVIEW was driven by size-level pricing review flag; defer size-level USD/variant pricing to pricing subtask. No Corrected_* fields needed.
A7: UPDATE | B7: =IF($D7="","",IF(COUNTA($Y7:$AE7)>0,"UPDATE","NO_CHANGE")) -> UPDATE | C7: =IF($D7="","",IF($R7<>"OK","ERROR",IF(OR($E7="", $F7="", $J7=""),"ERROR",IF($W7<>"OK","WARNING","PASS")))) -> WARNING | D7: =IF(DB_Artworks_Export!A7="","",DB_Artworks_Export!A7) -> art-1770775579766 | E7: =IF(DB_Artworks_Export!B7="","",DB_Artworks_Export!B7) -> Intricate Floral Mandala Art in Green & Gold | F7: =IF(DB_Artworks_Export!C7="","",DB_Artworks_Export!C7) -> dot-mandala | G7: =IF(DB_Artworks_Export!D7="","",DB_Artworks_Export!D7) -> Dot Mandala Art | H7: =IF(DB_Artworks_Export!E7="","",DB_Artworks_Export!E7) -> An exquisite hand-painted dot mandala artwork, created with intricate layers of delicate dots and flowing floral patterns. Painted in soothing green and warm gold tones, this mandala radiates harmony, balance, and timeless beauty. Every detail is carefully handcrafted, making each piece truly one of a kind. Perfect as a statement wall décor, shelf accent, or meditation centerpiece, this mandala art brings a sense of calm and elegance to living rooms, entryways, yoga spaces, or gifting occasions. A meaningful handmade gift for art lovers, housewarmings, weddings, or festive celebrations. | I7: =IF(DB_Artworks_Export!F7="","",DB_Artworks_Export!F7) -> wood | J7: =IF(DB_Artworks_Export!G7="","",DB_Artworks_Export!G7) -> 4000.00 | K7: =IF(DB_Artworks_Export!H7="","",DB_Artworks_Export!H7) -> 76.00 | ... Q7: =IF(DB_Artworks_Export!N7="","",DB_Artworks_Export!N7) -> 2026-03-17 03:31:03.464546 | R7: =IF($D7="","",IF(COUNTIF(DB_Categories_Export!$A:$A,$F7)>0,"OK","INVALID CATEGORY")) -> OK | S7: =IF($D7="","",COUNTIF(DB_Artwork_Sizes_Export!$B:$B,$D7)) -> 4 | T7: =IF($D7="","",IFERROR(INDEX(DB_Artwork_Sizes_Export!$D:$D,MATCH($D7,DB_Artwork_Sizes_Export!$B:$B,0)),"")) -> 12" round | U7: =IF($D7="","",IFERROR(INDEX(DB_Artwork_Sizes_Export!$E:$E,MATCH($D7,DB_Artwork_Sizes_Export!$B:$B,0)),"")) -> 4000.00 | V7: =IF($D7="","",IFERROR(INDEX(DB_Artwork_Sizes_Export!$F:$F,MATCH($D7,DB_Artwork_Sizes_Export!$B:$B,0)),"")) -> 76.00 | W7: =IF($D7="","",IF($S7>0,"REVIEW_SIZE_PRICING","OK")) -> REVIEW_SIZE_PRICING | AB7: Wood | AF7: =IF($Y7<>"",$Y7,$E7) -> Intricate Floral Mandala Art in Green & Gold | AG7: =IF($Z7<>"",$Z7,$F7) -> dot-mandala | AH7: =IF($AG7="","",IFERROR(VLOOKUP($AG7,DB_Categories_Export!$A:$B,2,FALSE()),"INVALID CATEGORY")) -> Dot Mandala Art | AI7: =IF($AA7<>"",$AA7,$H7) -> An exquisite hand-painted dot mandala artwork, created with intricate layers of delicate dots and flowing floral patterns. Painted in soothing green and warm gold tones, this mandala radiates harmony, balance, and timeless beauty. Every detail is carefully handcrafted, making each piece truly one of a kind. Perfect as a statement wall décor, shelf accent, or meditation centerpiece, this mandala art brings a sense of calm and elegance to living rooms, entryways, yoga spaces, or gifting occasions. A meaningful handmade gift for art lovers, housewarmings, weddings, or festive celebrations. | AJ7: =IF($AB7<>"",$AB7,$I7) -> Wood | AK7: =IF($AC7<>"",$AC7,$J7) -> 4000.00 | AL7: =IF($AD7<>"",$AD7,$N7) -> t | AM7: =IF($AE7<>"",$AE7,$O7) -> https://chitrakalaarts-production.up.railway.app/api/images/artworks/art-1770775579766
A8: NO_CHANGE | B8: =IF($D8="","",IF(COUNTA($Y8:$AE8)>0,"UPDATE","NO_CHANGE")) -> NO_CHANGE | C8: =IF($D8="","",IF($R8<>"OK","ERROR",IF(OR($E8="", $F8="", $J8=""),"ERROR",IF($W8<>"OK","WARNING","PASS")))) -> WARNING | D8: =IF(DB_Artworks_Export!A8="","",DB_Artworks_Export!A8) -> art-1770777152872 | E8: =IF(DB_Artworks_Export!B8="","",DB_Artworks_Export!B8) -> Sacred Geometry in Clay & Mirror | F8: =IF(DB_Artworks_Export!C8="","",DB_Artworks_Export!C8) -> lippan-art | G8: =IF(DB_Artworks_Export!D8="","",DB_Artworks_Export!D8) -> Lippan Art | H8: =IF(DB_Artworks_Export!E8="","",DB_Artworks_Export!E8) -> A stunning Lippan art panel handcrafted with clay motifs and delicate mirror inlays, radiating harmony through its geometric symmetry. Framed by vibrant earthy tones, it brings a serene glow to any space. | I8: =IF(DB_Artworks_Export!F8="","",DB_Artworks_Export!F8) -> Wood | J8: =IF(DB_Artworks_Export!G8="","",DB_Artworks_Export!G8) -> 8000.00 | K8: =IF(DB_Artworks_Export!H8="","",DB_Artworks_Export!H8) -> 152.00 | ... Q8: =IF(DB_Artworks_Export!N8="","",DB_Artworks_Export!N8) -> 2026-04-28 17:54:38.817767 | R8: =IF($D8="","",IF(COUNTIF(DB_Categories_Export!$A:$A,$F8)>0,"OK","INVALID CATEGORY")) -> OK | S8: =IF($D8="","",COUNTIF(DB_Artwork_Sizes_Export!$B:$B,$D8)) -> 2 | T8: =IF($D8="","",IFERROR(INDEX(DB_Artwork_Sizes_Export!$D:$D,MATCH($D8,DB_Artwork_Sizes_Export!$B:$B,0)),"")) -> 18" X 18" | U8: =IF($D8="","",IFERROR(INDEX(DB_Artwork_Sizes_Export!$E:$E,MATCH($D8,DB_Artwork_Sizes_Export!$B:$B,0)),"")) -> 8000.00 | V8: =IF($D8="","",IFERROR(INDEX(DB_Artwork_Sizes_Export!$F:$F,MATCH($D8,DB_Artwork_Sizes_Export!$B:$B,0)),"")) -> 152.00 | W8: =IF($D8="","",IF($S8>0,"REVIEW_SIZE_PRICING","OK")) -> REVIEW_SIZE_PRICING | AF8: =IF($Y8<>"",$Y8,$E8) -> Sacred Geometry in Clay & Mirror | AG8: =IF($Z8<>"",$Z8,$F8) -> lippan-art | AH8: =IF($AG8="","",IFERROR(VLOOKUP($AG8,DB_Categories_Export!$A:$B,2,FALSE()),"INVALID CATEGORY")) -> Lippan Art | AI8: =IF($AA8<>"",$AA8,$H8) -> A stunning Lippan art panel handcrafted with clay motifs and delicate mirror inlays, radiating harmony through its geometric symmetry. Framed by vibrant earthy tones, it brings a serene glow to any space. | AJ8: =IF($AB8<>"",$AB8,$I8) -> Wood | AK8: =IF($AC8<>"",$AC8,$J8) -> 8000.00 | AL8: =IF($AD8<>"",$AD8,$N8) -> f | AM8: =IF($AE8<>"",$AE8,$O8) -> https://chitrakalaarts-production.up.railway.app/api/images/artworks/art-1770777152872 | AO8: INV-03-01 reviewed: final action NO_CHANGE for artwork-level fields. Suggested Sync Action was NO_CHANGE and current artwork fields/category validate. REVIEW was driven by size-level pricing review flag; defer size-level USD/variant pricing to pricing subtask. No Corrected_* fields needed.
A9: NO_CHANGE | B9: =IF($D9="","",IF(COUNTA($Y9:$AE9)>0,"UPDATE","NO_CHANGE")) -> NO_CHANGE | C9: =IF($D9="","",IF($R9<>"OK","ERROR",IF(OR($E9="", $F9="", $J9=""),"ERROR",IF($W9<>"OK","WARNING","PASS")))) -> PASS | D9: =IF(DB_Artworks_Export!A9="","",DB_Artworks_Export!A9) -> art-1770778179564 | E9: =IF(DB_Artworks_Export!B9="","",DB_Artworks_Export!B9) -> Colorful Mandala KeyChain Holder | F9: =IF(DB_Artworks_Export!C9="","",DB_Artworks_Export!C9) -> dot-mandala | G9: =IF(DB_Artworks_Export!D9="","",DB_Artworks_Export!D9) -> Dot Mandala Art | H9: =IF(DB_Artworks_Export!E9="","",DB_Artworks_Export!E9) -> Handcrafted wooden key holder adorned with a vibrant dot mandala design in calming shades of purple and teal. Finished with sturdy hooks, it’s perfect for organizing keys while adding a touch of artistic elegance to your home décor. A beautiful blend of functionality and mindful art—ideal for entryways or as a thoughtful handmade gift. | I9: =IF(DB_Artworks_Export!F9="","",DB_Artworks_Export!F9) -> Wood | J9: =IF(DB_Artworks_Export!G9="","",DB_Artworks_Export!G9) -> 1000.00 | K9: =IF(DB_Artworks_Export!H9="","",DB_Artworks_Export!H9) -> 19.00 | ... Q9: =IF(DB_Artworks_Export!N9="","",DB_Artworks_Export!N9) -> 2026-03-17 03:31:03.453632 | R9: =IF($D9="","",IF(COUNTIF(DB_Categories_Export!$A:$A,$F9)>0,"OK","INVALID CATEGORY")) -> OK | S9: =IF($D9="","",COUNTIF(DB_Artwork_Sizes_Export!$B:$B,$D9)) -> 0 | T9: =IF($D9="","",IFERROR(INDEX(DB_Artwork_Sizes_Export!$D:$D,MATCH($D9,DB_Artwork_Sizes_Export!$B:$B,0)),"")) | U9: =IF($D9="","",IFERROR(INDEX(DB_Artwork_Sizes_Export!$E:$E,MATCH($D9,DB_Artwork_Sizes_Export!$B:$B,0)),"")) | V9: =IF($D9="","",IFERROR(INDEX(DB_Artwork_Sizes_Export!$F:$F,MATCH($D9,DB_Artwork_Sizes_Export!$B:$B,0)),"")) | W9: =IF($D9="","",IF($S9>0,"REVIEW_SIZE_PRICING","OK")) -> OK | AF9: =IF($Y9<>"",$Y9,$E9) -> Colorful Mandala KeyChain Holder | AG9: =IF($Z9<>"",$Z9,$F9) -> dot-mandala | AH9: =IF($AG9="","",IFERROR(VLOOKUP($AG9,DB_Categories_Export!$A:$B,2,FALSE()),"INVALID CATEGORY")) -> Dot Mandala Art | AI9: =IF($AA9<>"",$AA9,$H9) -> Handcrafted wooden key holder adorned with a vibrant dot mandala design in calming shades of purple and teal. Finished with sturdy hooks, it’s perfect for organizing keys while adding a touch of artistic elegance to your home décor. A beautiful blend of functionality and mindful art—ideal for entryways or as a thoughtful handmade gift. | AJ9: =IF($AB9<>"",$AB9,$I9) -> Wood | AK9: =IF($AC9<>"",$AC9,$J9) -> 1000.00 | AL9: =IF($AD9<>"",$AD9,$N9) -> f | AM9: =IF($AE9<>"",$AE9,$O9) -> https://chitrakalaarts-production.up.railway.app/api/images/artworks/art-1770778179564
A10: NO_CHANGE | B10: =IF($D10="","",IF(COUNTA($Y10:$AE10)>0,"UPDATE","NO_CHANGE")) -> NO_CHANGE | C10: =IF($D10="","",IF($R10<>"OK","ERROR",IF(OR($E10="", $F10="", $J10=""),"ERROR",IF($W10<>"OK","WARNING","PASS")))) -> WARNING | D10: =IF(DB_Artworks_Export!A10="","",DB_Artworks_Export!A10) -> art-1770778384172 | E10: =IF(DB_Artworks_Export!B10="","",DB_Artworks_Export!B10) -> Butterfly Set (3 pieces) | F10: =IF(DB_Artworks_Export!C10="","",DB_Artworks_Export!C10) -> dot-mandala | G10: =IF(DB_Artworks_Export!D10="","",DB_Artworks_Export!D10) -> Dot Mandala Art | H10: =IF(DB_Artworks_Export!E10="","",DB_Artworks_Export!E10) -> A graceful butterfly brought to life through intricate dot mandala artistry, this hand-painted piece symbolizes transformation, joy, and renewal. Rendered in warm shades of gold, green, and soft orange, each delicate dot adds depth, movement, and a gentle sense of harmony. Perfect as a mindful décor piece, this artwork radiates elegance and positive energy—an exquisite reminder of beauty in transformation. Available in set of 3 - 8*, 6", 4" | I10: =IF(DB_Artworks_Export!F10="","",DB_Artworks_Export!F10) -> Wood | J10: =IF(DB_Artworks_Export!G10="","",DB_Artworks_Export!G10) -> 1500.00 | K10: =IF(DB_Artworks_Export!H10="","",DB_Artworks_Export!H10) -> 28.00 | ... Q10: =IF(DB_Artworks_Export!N10="","",DB_Artworks_Export!N10) -> 2026-03-17 03:31:03.447787 | R10: =IF($D10="","",IF(COUNTIF(DB_Categories_Export!$A:$A,$F10)>0,"OK","INVALID CATEGORY")) -> OK | S10: =IF($D10="","",COUNTIF(DB_Artwork_Sizes_Export!$B:$B,$D10)) -> 1 | T10: =IF($D10="","",IFERROR(INDEX(DB_Artwork_Sizes_Export!$D:$D,MATCH($D10,DB_Artwork_Sizes_Export!$B:$B,0)),"")) -> 4", 6", 8" set | U10: =IF($D10="","",IFERROR(INDEX(DB_Artwork_Sizes_Export!$E:$E,MATCH($D10,DB_Artwork_Sizes_Export!$B:$B,0)),"")) -> 1500.00 | V10: =IF($D10="","",IFERROR(INDEX(DB_Artwork_Sizes_Export!$F:$F,MATCH($D10,DB_Artwork_Sizes_Export!$B:$B,0)),"")) -> 28.00 | W10: =IF($D10="","",IF($S10>0,"REVIEW_SIZE_PRICING","OK")) -> REVIEW_SIZE_PRICING | AF10: =IF($Y10<>"",$Y10,$E10) -> Butterfly Set (3 pieces) | AG10: =IF($Z10<>"",$Z10,$F10) -> dot-mandala | AH10: =IF($AG10="","",IFERROR(VLOOKUP($AG10,DB_Categories_Export!$A:$B,2,FALSE()),"INVALID CATEGORY")) -> Dot Mandala Art | AI10: =IF($AA10<>"",$AA10,$H10) -> A graceful butterfly brought to life through intricate dot mandala artistry, this hand-painted piece symbolizes transformation, joy, and renewal. Rendered in warm shades of gold, green, and soft orange, each delicate dot adds depth, movement, and a gentle sense of harmony. Perfect as a mindful décor piece, this artwork radiates elegance and positive energy—an exquisite reminder of beauty in transformation. Available in set of 3 - 8*, 6", 4" | AJ10: =IF($AB10<>"",$AB10,$I10) -> Wood | AK10: =IF($AC10<>"",$AC10,$J10) -> 1500.00 | AL10: =IF($AD10<>"",$AD10,$N10) -> f | AM10: =IF($AE10<>"",$AE10,$O10) -> https://chitrakalaarts-production.up.railway.app/api/images/artworks/art-1770778384172 | AO10: INV-03-01 reviewed: final action NO_CHANGE for artwork-level fields. Suggested Sync Action was NO_CHANGE and current artwork fields/category validate. REVIEW was driven by size-level pricing review flag; defer size-level USD/variant pricing to pricing subtask. No Corrected_* fields needed.
A11: NO_CHANGE | B11: =IF($D11="","",IF(COUNTA($Y11:$AE11)>0,"UPDATE","NO_CHANGE")) -> NO_CHANGE | C11: =IF($D11="","",IF($R11<>"OK","ERROR",IF(OR($E11="", $F11="", $J11=""),"ERROR",IF($W11<>"OK","WARNING","PASS")))) -> WARNING | D11: =IF(DB_Artworks_Export!A11="","",DB_Artworks_Export!A11) -> art-1770778509370 | E11: =IF(DB_Artworks_Export!B11="","",DB_Artworks_Export!B11) -> Coaster Set (4 pieces) | F11: =IF(DB_Artworks_Export!C11="","",DB_Artworks_Export!C11) -> dot-mandala | G11: =IF(DB_Artworks_Export!D11="","",DB_Artworks_Export!D11) -> Dot Mandala Art | H11: =IF(DB_Artworks_Export!E11="","",DB_Artworks_Export!E11) -> Add a touch of handcrafted elegance to your everyday moments with this hand-painted dot mandala coaster set. Each coaster is meticulously adorned with intricate dot patterns, radiating symmetry, balance, and calming energy. The rich colors and delicate detailing create a harmonious blend of art and function, protecting your surfaces while elevating your décor. Perfect for tea tables, coffee corners, or thoughtful gifting, this coaster set brings mindful beauty and artisanal charm into every sip. Set of 4 - Rs 750 Set of 6 - Rs 1000 | I11: =IF(DB_Artworks_Export!F11="","",DB_Artworks_Export!F11) -> Wood | J11: =IF(DB_Artworks_Export!G11="","",DB_Artworks_Export!G11) -> 800.00 | K11: =IF(DB_Artworks_Export!H11="","",DB_Artworks_Export!H11) -> 15.00 | ... Q11: =IF(DB_Artworks_Export!N11="","",DB_Artworks_Export!N11) -> 2026-03-17 03:31:03.442637 | R11: =IF($D11="","",IF(COUNTIF(DB_Categories_Export!$A:$A,$F11)>0,"OK","INVALID CATEGORY")) -> OK | S11: =IF($D11="","",COUNTIF(DB_Artwork_Sizes_Export!$B:$B,$D11)) -> 4 | T11: =IF($D11="","",IFERROR(INDEX(DB_Artwork_Sizes_Export!$D:$D,MATCH($D11,DB_Artwork_Sizes_Export!$B:$B,0)),"")) -> 4" (set of 4) | U11: =IF($D11="","",IFERROR(INDEX(DB_Artwork_Sizes_Export!$E:$E,MATCH($D11,DB_Artwork_Sizes_Export!$B:$B,0)),"")) -> 800.00 | V11: =IF($D11="","",IFERROR(INDEX(DB_Artwork_Sizes_Export!$F:$F,MATCH($D11,DB_Artwork_Sizes_Export!$B:$B,0)),"")) -> 15.00 | W11: =IF($D11="","",IF($S11>0,"REVIEW_SIZE_PRICING","OK")) -> REVIEW_SIZE_PRICING | AF11: =IF($Y11<>"",$Y11,$E11) -> Coaster Set (4 pieces) | AG11: =IF($Z11<>"",$Z11,$F11) -> dot-mandala | AH11: =IF($AG11="","",IFERROR(VLOOKUP($AG11,DB_Categories_Export!$A:$B,2,FALSE()),"INVALID CATEGORY")) -> Dot Mandala Art | AI11: =IF($AA11<>"",$AA11,$H11) -> Add a touch of handcrafted elegance to your everyday moments with this hand-painted dot mandala coaster set. Each coaster is meticulously adorned with intricate dot patterns, radiating symmetry, balance, and calming energy. The rich colors and delicate detailing create a harmonious blend of art and function, protecting your surfaces while elevating your décor. Perfect for tea tables, coffee corners, or thoughtful gifting, this coaster set brings mindful beauty and artisanal charm into every sip. Set of 4 - Rs 750 Set of 6 - Rs 1000 | AJ11: =IF($AB11<>"",$AB11,$I11) -> Wood | AK11: =IF($AC11<>"",$AC11,$J11) -> 800.00 | AL11: =IF($AD11<>"",$AD11,$N11) -> f | AM11: =IF($AE11<>"",$AE11,$O11) -> https://chitrakalaarts-production.up.railway.app/api/images/artworks/art-1770778509370 | AO11: INV-03-01 reviewed: final action NO_CHANGE for artwork-level fields. Suggested Sync Action was NO_CHANGE and current artwork fields/category validate. REVIEW was driven by size-level pricing review flag; defer size-level USD/variant pricing to pricing subtask. No Corrected_* fields needed.
A12: NO_CHANGE | B12: =IF($D12="","",IF(COUNTA($Y12:$AE12)>0,"UPDATE","NO_CHANGE")) -> NO_CHANGE | C12: =IF($D12="","",IF($R12<>"OK","ERROR",IF(OR($E12="", $F12="", $J12=""),"ERROR",IF($W12<>"OK","WARNING","PASS")))) -> PASS | D12: =IF(DB_Artworks_Export!A12="","",DB_Artworks_Export!A12) -> art-1770778808201 | E12: =IF(DB_Artworks_Export!B12="","",DB_Artworks_Export!B12) -> Serene Teal Floral Mandala Box | F12: =IF(DB_Artworks_Export!C12="","",DB_Artworks_Export!C12) -> dot-mandala | G12: =IF(DB_Artworks_Export!D12="","",DB_Artworks_Export!D12) -> Dot Mandala Art | H12: =IF(DB_Artworks_Export!E12="","",DB_Artworks_Export!E12) -> Hand-painted dot mandala box in soothing teal and turquoise tones, adorned with intricate floral patterns. A perfect accent piece for storing jewelry, keys, or small keepsakes—bringing calm, color, and handmade charm to any space | I12: =IF(DB_Artworks_Export!F12="","",DB_Artworks_Export!F12) -> Wood | J12: =IF(DB_Artworks_Export!G12="","",DB_Artworks_Export!G12) -> 1000.00 | K12: =IF(DB_Artworks_Export!H12="","",DB_Artworks_Export!H12) -> 19.00 | ... Q12: =IF(DB_Artworks_Export!N12="","",DB_Artworks_Export!N12) -> 2026-03-17 03:31:03.439328 | R12: =IF($D12="","",IF(COUNTIF(DB_Categories_Export!$A:$A,$F12)>0,"OK","INVALID CATEGORY")) -> OK | S12: =IF($D12="","",COUNTIF(DB_Artwork_Sizes_Export!$B:$B,$D12)) -> 0 | T12: =IF($D12="","",IFERROR(INDEX(DB_Artwork_Sizes_Export!$D:$D,MATCH($D12,DB_Artwork_Sizes_Export!$B:$B,0)),"")) | U12: =IF($D12="","",IFERROR(INDEX(DB_Artwork_Sizes_Export!$E:$E,MATCH($D12,DB_Artwork_Sizes_Export!$B:$B,0)),"")) | V12: =IF($D12="","",IFERROR(INDEX(DB_Artwork_Sizes_Export!$F:$F,MATCH($D12,DB_Artwork_Sizes_Export!$B:$B,0)),"")) | W12: =IF($D12="","",IF($S12>0,"REVIEW_SIZE_PRICING","OK")) -> OK | AF12: =IF($Y12<>"",$Y12,$E12) -> Serene Teal Floral Mandala Box | AG12: =IF($Z12<>"",$Z12,$F12) -> dot-mandala | AH12: =IF($AG12="","",IFERROR(VLOOKUP($AG12,DB_Categories_Export!$A:$B,2,FALSE()),"INVALID CATEGORY")) -> Dot Mandala Art | AI12: =IF($AA12<>"",$AA12,$H12) -> Hand-painted dot mandala box in soothing teal and turquoise tones, adorned with intricate floral patterns. A perfect accent piece for storing jewelry, keys, or small keepsakes—bringing calm, color, and handmade charm to any space | AJ12: =IF($AB12<>"",$AB12,$I12) -> Wood | AK12: =IF($AC12<>"",$AC12,$J12) -> 1000.00 | AL12: =IF($AD12<>"",$AD12,$N12) -> f | AM12: =IF($AE12<>"",$AE12,$O12) -> https://chitrakalaarts-production.up.railway.app/api/images/artworks/art-1770778808201
A13: NO_CHANGE | B13: =IF($D13="","",IF(COUNTA($Y13:$AE13)>0,"UPDATE","NO_CHANGE")) -> NO_CHANGE | C13: =IF($D13="","",IF($R13<>"OK","ERROR",IF(OR($E13="", $F13="", $J13=""),"ERROR",IF($W13<>"OK","WARNING","PASS")))) -> WARNING | D13: =IF(DB_Artworks_Export!A13="","",DB_Artworks_Export!A13) -> art-1770779054676 | E13: =IF(DB_Artworks_Export!B13="","",DB_Artworks_Export!B13) -> Floral Rectangular Wooden Storage Box | F13: =IF(DB_Artworks_Export!C13="","",DB_Artworks_Export!C13) -> dot-mandala | G13: =IF(DB_Artworks_Export!D13="","",DB_Artworks_Export!D13) -> Dot Mandala Art | H13: =IF(DB_Artworks_Export!E13="","",DB_Artworks_Export!E13) -> Bring vibrant artistry into your home with this beautifully hand‑painted rectangular wooden storage box. Featuring an intricate floral design in rich shades of orange, green, mustard, and white, the artwork is set against a deep, elegant background that makes every detail pop. The flowing patterns and delicate dot work create a striking centerpiece that reflects traditional craftsmanship with a modern touch. | I13: =IF(DB_Artworks_Export!F13="","",DB_Artworks_Export!F13) -> Wood | J13: =IF(DB_Artworks_Export!G13="","",DB_Artworks_Export!G13) -> 1500.00 | K13: =IF(DB_Artworks_Export!H13="","",DB_Artworks_Export!H13) -> 28.00 | ... Q13: =IF(DB_Artworks_Export!N13="","",DB_Artworks_Export!N13) -> 2026-03-17 03:31:03.43306 | R13: =IF($D13="","",IF(COUNTIF(DB_Categories_Export!$A:$A,$F13)>0,"OK","INVALID CATEGORY")) -> OK | S13: =IF($D13="","",COUNTIF(DB_Artwork_Sizes_Export!$B:$B,$D13)) -> 2 | T13: =IF($D13="","",IFERROR(INDEX(DB_Artwork_Sizes_Export!$D:$D,MATCH($D13,DB_Artwork_Sizes_Export!$B:$B,0)),"")) -> 12" X 5" X 3" (2 partitions) | U13: =IF($D13="","",IFERROR(INDEX(DB_Artwork_Sizes_Export!$E:$E,MATCH($D13,DB_Artwork_Sizes_Export!$B:$B,0)),"")) -> 1500.00 | V13: =IF($D13="","",IFERROR(INDEX(DB_Artwork_Sizes_Export!$F:$F,MATCH($D13,DB_Artwork_Sizes_Export!$B:$B,0)),"")) -> 28.00 | W13: =IF($D13="","",IF($S13>0,"REVIEW_SIZE_PRICING","OK")) -> REVIEW_SIZE_PRICING | AF13: =IF($Y13<>"",$Y13,$E13) -> Floral Rectangular Wooden Storage Box | AG13: =IF($Z13<>"",$Z13,$F13) -> dot-mandala | AH13: =IF($AG13="","",IFERROR(VLOOKUP($AG13,DB_Categories_Export!$A:$B,2,FALSE()),"INVALID CATEGORY")) -> Dot Mandala Art | AI13: =IF($AA13<>"",$AA13,$H13) -> Bring vibrant artistry into your home with this beautifully hand‑painted rectangular wooden storage box. Featuring an intricate floral design in rich shades of orange, green, mustard, and white, the artwork is set against a deep, elegant background that makes every detail pop. The flowing patterns and delicate dot work create a striking centerpiece that reflects traditional craftsmanship with a modern touch. | AJ13: =IF($AB13<>"",$AB13,$I13) -> Wood | AK13: =IF($AC13<>"",$AC13,$J13) -> 1500.00 | AL13: =IF($AD13<>"",$AD13,$N13) -> f | AM13: =IF($AE13<>"",$AE13,$O13) -> https://chitrakalaarts-production.up.railway.app/api/images/artworks/art-1770779054676 | AO13: INV-03-01 reviewed: final action NO_CHANGE for artwork-level fields. Suggested Sync Action was NO_CHANGE and current artwork fields/category validate. REVIEW was driven by size-level pricing review flag; defer size-level USD/variant pricing to pricing subtask. No Corrected_* fields needed.
